<sdf version='1.7'>
  <world name='default'>
    <light name='sun' type='directional'>
      <cast_shadows>1</cast_shadows>
      <pose>0 0 10 0 -0 0</pose>
      <diffuse>0.8 0.8 0.8 1</diffuse>
      <specular>0.2 0.2 0.2 1</specular>
      <attenuation>
        <range>1000</range>
        <constant>0.9</constant>
        <linear>0.01</linear>
        <quadratic>0.001</quadratic>
      </attenuation>
      <direction>-0.5 0.1 -0.9</direction>
      <spot>
        <inner_angle>0</inner_angle>
        <outer_angle>0</outer_angle>
        <falloff>0</falloff>
      </spot>
    </light>
    <model name='ground_plane'>
      <static>1</static>
      <link name='link'>
        <collision name='collision'>
          <geometry>
            <plane>
              <normal>0 0 1</normal>
              <size>100 100</size>
            </plane>
          </geometry>
          <surface>
            <friction>
              <ode>
                <mu>100</mu>
                <mu2>50</mu2>
              </ode>
              <torsional>
                <ode/>
              </torsional>
            </friction>
            <contact>
              <ode/>
            </contact>
            <bounce/>
          </surface>
          <max_contacts>10</max_contacts>
        </collision>
        <visual name='visual'>
          <cast_shadows>0</cast_shadows>
          <geometry>
            <plane>
              <normal>0 0 1</normal>
              <size>100 100</size>
            </plane>
          </geometry>
          <material>
            <script>
              <uri>file://media/materials/scripts/gazebo.material</uri>
              <name>Gazebo/Grey</name>
            </script>
          </material>
        </visual>
        <self_collide>0</self_collide>
        <enable_wind>0</enable_wind>
        <kinematic>0</kinematic>
      </link>
    </model>
    <gravity>0 0 -9.8</gravity>
    <magnetic_field>6e-06 2.3e-05 -4.2e-05</magnetic_field>
    <atmosphere type='adiabatic'/>
    <physics type='ode'>
      <max_step_size>0.001</max_step_size>
      <real_time_factor>1</real_time_factor>
      <real_time_update_rate>1000</real_time_update_rate>
    </physics>
    <scene>
      <ambient>0.4 0.4 0.4 1</ambient>
      <background>0.7 0.7 0.7 1</background>
      <shadows>1</shadows>
    </scene>
    <wind/>
    <spherical_coordinates>
      <surface_model>EARTH_WGS84</surface_model>
      <latitude_deg>0</latitude_deg>
      <longitude_deg>0</longitude_deg>
      <elevation>0</elevation>
      <heading_deg>0</heading_deg>
    </spherical_coordinates>
    <state world_name='default'>
      <sim_time>212 577000000</sim_time>
      <real_time>83 778308477</real_time>
      <wall_time>1734078553 683878774</wall_time>
      <iterations>72994</iterations>
      <model name='abuRobocon_wall'>
        <pose>-0.006702 0.07141 0 0 -0 0</pose>
        <scale>1 1 1</scale>
        <link name='Wall_38'>
          <pose>-0.00387 -7.48372 0 0 0 -0.000398</pose>
          <velocity>0 0 0 0 -0 0</velocity>
          <acceleration>0 0 0 0 -0 0</acceleration>
          <wrench>0 0 0 0 -0 0</wrench>
        </link>
        <link name='Wall_45'>
          <pose>-0.003159 7.62816 0 0 -0 3.14159</pose>
          <velocity>0 0 0 0 -0 0</velocity>
          <acceleration>0 0 0 0 -0 0</acceleration>
          <wrench>0 0 0 0 -0 0</wrench>
        </link>
        <link name='Wall_47'>
          <pose>4.03281 0.069111 0 0 -0 1.57225</pose>
          <velocity>0 0 0 0 -0 0</velocity>
          <acceleration>0 0 0 0 -0 0</acceleration>
          <wrench>0 0 0 0 -0 0</wrench>
        </link>
        <link name='Wall_53'>
          <pose>-4.04266 0.069797 0 0 -0 1.56888</pose>
          <velocity>0 0 0 0 -0 0</velocity>
          <acceleration>0 0 0 0 -0 0</acceleration>
          <wrench>0 0 0 0 -0 0</wrench>
        </link>
      </model>
      <model name='ground_plane'>
        <pose>0 0 0 0 -0 0</pose>
        <scale>1 1 1</scale>
        <link name='link'>
          <pose>0 0 0 0 -0 0</pose>
          <velocity>0 0 0 0 -0 0</velocity>
          <acceleration>0 0 0 0 -0 0</acceleration>
          <wrench>0 0 0 0 -0 0</wrench>
        </link>
      </model>
      <model name='linorobot2'>
        <pose>-2.00584 -6.7009 -0 0 -0 1.57093</pose>
        <scale>1 1 1</scale>
        <link name='base_footprint'>
          <pose>-2.00584 -6.7009 -0 0 -0 1.57093</pose>
          <velocity>0.000813 -0.000477 0.007488 -0.005323 -0.005838 -3e-06</velocity>
          <acceleration>-0.120267 0.37263 15.0086 -2.24285 1.52751 -0.053301</acceleration>
          <wrench>-1.23093 3.81386 153.613 0 -0 0</wrench>
        </link>
        <link name='front_left_wheel_link'>
          <pose>-2.25588 -6.45094 0.07162 0 0.130427 0.785537</pose>
          <velocity>0.000405 -0.000111 0.004695 -0.007141 -0.004077 2.6e-05</velocity>
          <acceleration>1.02518 -0.699535 3.91545 -0.303268 0.30944 3.08657</acceleration>
          <wrench>0.615109 -0.419721 2.34927 0 -0 0</wrench>
        </link>
        <link name='front_right_wheel_link'>
          <pose>-1.75588 -6.45087 0.07162 1e-06 -0.179141 2.35633</pose>
          <velocity>0.00032 -0.000165 0.007693 0.0023 0.004468 -6e-06</velocity>
          <acceleration>0.950131 -0.803376 15.3969 -1.14498 -0.3546 3.10304</acceleration>
          <wrench>0.570079 -0.482026 9.23817 0 -0 0</wrench>
        </link>
        <link name='rear_left_wheel_link'>
          <pose>-2.25581 -6.95094 0.07162 1e-06 -0.304576 2.35633</pose>
          <velocity>0.000326 -0.000158 0.007451 0.002201 0.004553 -8e-06</velocity>
          <acceleration>0.936447 -0.773306 14.9103 -1.37137 -0.232726 3.10724</acceleration>
          <wrench>0.561868 -0.463983 8.94619 0 -0 0</wrench>
        </link>
        <link name='rear_right_wheel_link'>
          <pose>-1.75581 -6.95087 0.07162 -4e-06 0.185617 0.785536</pose>
          <velocity>0.000424 -0.000121 0.0102 -0.007987 -0.004675 1.5e-05</velocity>
          <acceleration>1.00594 -0.7181 26.1549 -0.744119 0.756869 3.09321</acceleration>
          <wrench>0.603562 -0.43086 15.6929 0 -0 0</wrench>
        </link>
      </model>
      <light name='sun'>
        <pose>0 0 10 0 -0 0</pose>
      </light>
      <light name='user_directional_light_0'>
        <pose>-5.63054 -11.2657 1 0 -0 0</pose>
      </light>
      <light name='user_directional_light_1'>
        <pose>10.4762 9.60881 1 0 -0 0</pose>
      </light>
    </state>
    <light name='user_directional_light_0' type='directional'>
      <pose>-5.63054 -11.2657 1 0 -0 0</pose>
      <diffuse>0.5 0.5 0.5 1</diffuse>
      <specular>0.1 0.1 0.1 1</specular>
      <direction>0.1 0.1 -0.9</direction>
      <attenuation>
        <range>20</range>
        <constant>0.5</constant>
        <linear>0.01</linear>
        <quadratic>0.001</quadratic>
      </attenuation>
      <cast_shadows>1</cast_shadows>
      <spot>
        <inner_angle>0</inner_angle>
        <outer_angle>0</outer_angle>
        <falloff>0</falloff>
      </spot>
    </light>
    <light name='user_directional_light_1' type='directional'>
      <pose>10.4762 9.60881 1 0 -0 0</pose>
      <diffuse>0.5 0.5 0.5 1</diffuse>
      <specular>0.1 0.1 0.1 1</specular>
      <direction>0.1 0.1 -0.9</direction>
      <attenuation>
        <range>20</range>
        <constant>0.5</constant>
        <linear>0.01</linear>
        <quadratic>0.001</quadratic>
      </attenuation>
      <cast_shadows>1</cast_shadows>
      <spot>
        <inner_angle>0</inner_angle>
        <outer_angle>0</outer_angle>
        <falloff>0</falloff>
      </spot>
    </light>
    <gui fullscreen='0'>
      <camera name='user_camera'>
        <pose>1.62391 -5.44255 22.4685 0 1.4138 1.56418</pose>
        <view_controller>orbit</view_controller>
        <projection_type>perspective</projection_type>
      </camera>
    </gui>
    <audio>
      <device>default</device>
    </audio>
    <model name='linorobot2'>
      <link name='base_footprint'>
        <inertial>
          <pose>0.002669 0 0.121513 0 -0 0</pose>
          <mass>10.235</mass>
          <inertia>
            <ixx>0.224447</ixx>
            <ixy>0</ixy>
            <ixz>-0.00127503</ixz>
            <iyy>0.232052</iyy>
            <iyz>0</iyz>
            <izz>0.424674</izz>
          </inertia>
        </inertial>
        <collision name='base_footprint_fixed_joint_lump__base_link_collision'>
          <pose>0 0 0.1195 0 -0 0</pose>
          <geometry>
            <box>
              <size>0.5 0.5 0.129</size>
            </box>
          </geometry>
          <surface>
            <contact>
              <ode/>
            </contact>
            <friction>
              <ode/>
              <torsional>
                <ode/>
              </torsional>
            </friction>
            <bounce/>
          </surface>
          <max_contacts>10</max_contacts>
        </collision>
        <collision name='base_footprint_fixed_joint_lump__camera_link_collision_1'>
          <pose>0.2375 0 0.1795 0 -0 0</pose>
          <geometry>
            <box>
              <size>0.03 0.124 0.03</size>
            </box>
          </geometry>
          <surface>
            <contact>
              <ode/>
            </contact>
            <friction>
              <ode/>
              <torsional>
                <ode/>
              </torsional>
            </friction>
            <bounce/>
          </surface>
          <max_contacts>10</max_contacts>
        </collision>
        <collision name='base_footprint_fixed_joint_lump__laser_collision_2'>
          <pose>-0.0475 0 0.2195 0 -0 0</pose>
          <geometry>
            <cylinder>
              <length>0.05</length>
              <radius>0.0375</radius>
            </cylinder>
          </geometry>
          <surface>
            <contact>
              <ode/>
            </contact>
            <friction>
              <ode/>
              <torsional>
                <ode/>
              </torsional>
            </friction>
            <bounce/>
          </surface>
          <max_contacts>10</max_contacts>
        </collision>
        <visual name='base_footprint_fixed_joint_lump__base_link_visual'>
          <pose>0 0 0.1195 0 -0 0</pose>
          <geometry>
            <box>
              <size>0.5 0.5 0.129</size>
            </box>
          </geometry>
          <material>
            <ambient>0.8392 0.6314 0 1</ambient>
            <diffuse>0.8392 0.6314 0 1</diffuse>
            <specular>0.99 0.99 0.99 1</specular>
            <emissive>0 0 0 0</emissive>
          </material>
        </visual>
        <visual name='base_footprint_fixed_joint_lump__camera_link_visual_1'>
          <pose>0.2375 0 0.1795 0 -0 0</pose>
          <geometry>
            <box>
              <size>0.03 0.124 0.03</size>
            </box>
          </geometry>
          <material>
            <ambient>0.416 0.051 0.047 1</ambient>
            <diffuse>0.416 0.051 0.047 1</diffuse>
            <specular>0.416 0.051 0.047 1</specular>
            <emissive>0.416 0.051 0.047 1</emissive>
          </material>
        </visual>
        <visual name='base_footprint_fixed_joint_lump__laser_visual_2'>
          <pose>-0.0475 0 0.2195 0 -0 0</pose>
          <geometry>
            <cylinder>
              <length>0.05</length>
              <radius>0.0375</radius>
            </cylinder>
          </geometry>
          <material>
            <ambient>0.003 0.639 0.223 1</ambient>
            <diffuse>0.003 0.639 0.223 1</diffuse>
            <specular>0.003 0.639 0.223 1</specular>
            <emissive>0 0 0 0</emissive>
          </material>
        </visual>
        <sensor name='camera' type='depth'>
          <always_on>1</always_on>
          <update_rate>30</update_rate>
          <camera name='camera'>
            <horizontal_fov>1.50098</horizontal_fov>
            <image>
              <width>640</width>
              <height>480</height>
              <format>R8G8B8</format>
            </image>
            <clip>
              <near>0.1</near>
              <far>100</far>
            </clip>
          </camera>
          <plugin name='camera_controller' filename='libgazebo_ros_camera.so'>
            <ros>
              <remapping>/camera/camera_info:=/camera/color/camera_info</remapping>
              <remapping>/camera/image_raw:=/camera/color/image_raw</remapping>
              <remapping>/camera/points:=/camera/depth/color/points</remapping>
              <remapping>/camera/depth/image_raw:=/camera/depth/image_rect_raw</remapping>
              <qos>
                <topic name='/camera/depth/color/points'>
                  <publisher>
                    <reliability>best_effort</reliability>
                  </publisher>
                </topic>
              </qos>
            </ros>
            <min_depth>0.015</min_depth>
            <max_depth>3.0</max_depth>
            <hack_baseline>0.07</hack_baseline>
            <frame_name>camera_depth_link</frame_name>
            <distortion_k1>0.00000001</distortion_k1>
            <distortion_k2>0.00000001</distortion_k2>
            <distortion_k3>0.00000001</distortion_k3>
            <distortion_t1>0.00000001</distortion_t1>
            <distortion_t2>0.00000001</distortion_t2>
          </plugin>
          <pose>0.2375 0 0.1795 0 -0 0</pose>
        </sensor>
        <gravity>1</gravity>
        <sensor name='imu_sensor' type='imu'>
          <always_on>1</always_on>
          <update_rate>20</update_rate>
          <visualize>1</visualize>
          <topic>__default_topic__</topic>
          <plugin name='imu_plugin' filename='libgazebo_ros_imu_sensor.so'>
            <ros>
              <remapping>~/out:=imu/data</remapping>
            </ros>
            <topicName>imu/data</topicName>
            <bodyName>imu_link</bodyName>
            <updateRateHZ>10.0</updateRateHZ>
            <gaussianNoise>0.0</gaussianNoise>
            <xyzOffset>0 0 0</xyzOffset>
            <rpyOffset>0 0 0</rpyOffset>
            <frameName>imu_link</frameName>
            <initialOrientationAsReference>0</initialOrientationAsReference>
          </plugin>
          <pose>0 0 0.1195 0 -0 0</pose>
          <imu/>
        </sensor>
        <sensor name='laser_lidar' type='ray'>
          <always_on>1</always_on>
          <update_rate>10</update_rate>
          <visualize>0</visualize>
          <ray>
            <scan>
              <horizontal>
                <samples>360</samples>
                <resolution>1</resolution>
                <min_angle>-3.1416</min_angle>
                <max_angle>3.1416</max_angle>
              </horizontal>
              <vertical>
                <samples>1</samples>
                <min_angle>0</min_angle>
                <max_angle>0</max_angle>
              </vertical>
            </scan>
            <range>
              <min>0.08</min>
              <max>12</max>
              <resolution>0.01</resolution>
            </range>
          </ray>
          <plugin name='laser_lidar_controller' filename='libgazebo_ros_ray_sensor.so'>
            <ros>
              <remapping>~/out:=scan</remapping>
            </ros>
            <output_type>sensor_msgs/LaserScan</output_type>
            <alwaysOn>1</alwaysOn>
            <updateRate>10</updateRate>
            <topicName>scan</topicName>
            <frame_name>laser</frame_name>
            <output_type>sensor_msgs/LaserScan</output_type>
          </plugin>
          <pose>-0.0475 0 0.2445 0 -0 0</pose>
        </sensor>
        <self_collide>0</self_collide>
        <enable_wind>0</enable_wind>
        <kinematic>0</kinematic>
      </link>
      <joint name='front_left_wheel_joint' type='revolute'>
        <pose relative_to='base_footprint'>0.25 0.25 0.07162 0 0 -0.785398</pose>
        <parent>base_footprint</parent>
        <child>front_left_wheel_link</child>
        <axis>
          <xyz>0 1 0</xyz>
          <limit>
            <lower>-1e+16</lower>
            <upper>1e+16</upper>
          </limit>
          <dynamics>
            <spring_reference>0</spring_reference>
            <spring_stiffness>0</spring_stiffness>
          </dynamics>
        </axis>
      </joint>
      <link name='front_left_wheel_link'>
        <pose relative_to='front_left_wheel_joint'>0 0 0 0 -0 0</pose>
        <inertial>
          <pose>0 0 0 0 -0 0</pose>
          <mass>0.6</mass>
          <inertia>
            <ixx>0.00123106</ixx>
            <ixy>0</ixy>
            <ixz>0</ixz>
            <iyy>0.00123106</iyy>
            <iyz>0</iyz>
            <izz>0.00123106</izz>
          </inertia>
        </inertial>
        <collision name='front_left_wheel_link_collision'>
          <pose>0 0 0 1.5708 -0 0</pose>
          <geometry>
            <cylinder>
              <length>0.05</length>
              <radius>0.07162</radius>
            </cylinder>
          </geometry>
          <surface>
            <contact>
              <ode/>
            </contact>
            <friction>
              <ode>
                <mu>0.01</mu>
                <mu2>0.01</mu2>
              </ode>
              <torsional>
                <ode/>
              </torsional>
            </friction>
            <bounce/>
          </surface>
          <max_contacts>10</max_contacts>
        </collision>
        <visual name='front_left_wheel_link_visual'>
          <pose>0 0 0 1.5708 -0 0</pose>
          <geometry>
            <cylinder>
              <length>0.05</length>
              <radius>0.07162</radius>
            </cylinder>
          </geometry>
          <material>
            <ambient>0.1764 0.4588 0.8509 1</ambient>
            <diffuse>0.1764 0.4588 0.8509 1</diffuse>
            <specular>0.1764 0.4588 0.8509 1</specular>
            <emissive>0 0 0 0</emissive>
          </material>
        </visual>
        <self_collide>0</self_collide>
        <enable_wind>0</enable_wind>
        <kinematic>0</kinematic>
      </link>
      <joint name='front_right_wheel_joint' type='revolute'>
        <pose relative_to='base_footprint'>0.25 -0.25 0.07162 0 -0 0.785398</pose>
        <parent>base_footprint</parent>
        <child>front_right_wheel_link</child>
        <axis>
          <xyz>0 1 0</xyz>
          <limit>
            <lower>-1e+16</lower>
            <upper>1e+16</upper>
          </limit>
          <dynamics>
            <spring_reference>0</spring_reference>
            <spring_stiffness>0</spring_stiffness>
          </dynamics>
        </axis>
      </joint>
      <link name='front_right_wheel_link'>
        <pose relative_to='front_right_wheel_joint'>0 0 0 0 -0 0</pose>
        <inertial>
          <pose>0 0 0 0 -0 0</pose>
          <mass>0.6</mass>
          <inertia>
            <ixx>0.00123106</ixx>
            <ixy>0</ixy>
            <ixz>0</ixz>
            <iyy>0.00123106</iyy>
            <iyz>0</iyz>
            <izz>0.00123106</izz>
          </inertia>
        </inertial>
        <collision name='front_right_wheel_link_collision'>
          <pose>0 0 0 1.5708 -0 0</pose>
          <geometry>
            <cylinder>
              <length>0.05</length>
              <radius>0.07162</radius>
            </cylinder>
          </geometry>
          <surface>
            <contact>
              <ode/>
            </contact>
            <friction>
              <ode>
                <mu>0.01</mu>
                <mu2>0.01</mu2>
              </ode>
              <torsional>
                <ode/>
              </torsional>
            </friction>
            <bounce/>
          </surface>
          <max_contacts>10</max_contacts>
        </collision>
        <visual name='front_right_wheel_link_visual'>
          <pose>0 0 0 1.5708 -0 0</pose>
          <geometry>
            <cylinder>
              <length>0.05</length>
              <radius>0.07162</radius>
            </cylinder>
          </geometry>
          <material>
            <ambient>0.1764 0.4588 0.8509 1</ambient>
            <diffuse>0.1764 0.4588 0.8509 1</diffuse>
            <specular>0.1764 0.4588 0.8509 1</specular>
            <emissive>0 0 0 0</emissive>
          </material>
        </visual>
        <self_collide>0</self_collide>
        <enable_wind>0</enable_wind>
        <kinematic>0</kinematic>
      </link>
      <joint name='rear_left_wheel_joint' type='revolute'>
        <pose relative_to='base_footprint'>-0.25 0.25 0.07162 0 -0 0.785398</pose>
        <parent>base_footprint</parent>
        <child>rear_left_wheel_link</child>
        <axis>
          <xyz>0 1 0</xyz>
          <limit>
            <lower>-1e+16</lower>
            <upper>1e+16</upper>
          </limit>
          <dynamics>
            <spring_reference>0</spring_reference>
            <spring_stiffness>0</spring_stiffness>
          </dynamics>
        </axis>
      </joint>
      <link name='rear_left_wheel_link'>
        <pose relative_to='rear_left_wheel_joint'>0 0 0 0 -0 0</pose>
        <inertial>
          <pose>0 0 0 0 -0 0</pose>
          <mass>0.6</mass>
          <inertia>
            <ixx>0.00123106</ixx>
            <ixy>0</ixy>
            <ixz>0</ixz>
            <iyy>0.00123106</iyy>
            <iyz>0</iyz>
            <izz>0.00123106</izz>
          </inertia>
        </inertial>
        <collision name='rear_left_wheel_link_collision'>
          <pose>0 0 0 1.5708 -0 0</pose>
          <geometry>
            <cylinder>
              <length>0.05</length>
              <radius>0.07162</radius>
            </cylinder>
          </geometry>
          <surface>
            <contact>
              <ode/>
            </contact>
            <friction>
              <ode>
                <mu>0.01</mu>
                <mu2>0.01</mu2>
              </ode>
              <torsional>
                <ode/>
              </torsional>
            </friction>
            <bounce/>
          </surface>
          <max_contacts>10</max_contacts>
        </collision>
        <visual name='rear_left_wheel_link_visual'>
          <pose>0 0 0 1.5708 -0 0</pose>
          <geometry>
            <cylinder>
              <length>0.05</length>
              <radius>0.07162</radius>
            </cylinder>
          </geometry>
          <material>
            <ambient>0.1764 0.4588 0.8509 1</ambient>
            <diffuse>0.1764 0.4588 0.8509 1</diffuse>
            <specular>0.1764 0.4588 0.8509 1</specular>
            <emissive>0 0 0 0</emissive>
          </material>
        </visual>
        <self_collide>0</self_collide>
        <enable_wind>0</enable_wind>
        <kinematic>0</kinematic>
      </link>
      <joint name='rear_right_wheel_joint' type='revolute'>
        <pose relative_to='base_footprint'>-0.25 -0.25 0.07162 0 0 -0.785398</pose>
        <parent>base_footprint</parent>
        <child>rear_right_wheel_link</child>
        <axis>
          <xyz>0 1 0</xyz>
          <limit>
            <lower>-1e+16</lower>
            <upper>1e+16</upper>
          </limit>
          <dynamics>
            <spring_reference>0</spring_reference>
            <spring_stiffness>0</spring_stiffness>
          </dynamics>
        </axis>
      </joint>
      <link name='rear_right_wheel_link'>
        <pose relative_to='rear_right_wheel_joint'>0 0 0 0 -0 0</pose>
        <inertial>
          <pose>0 0 0 0 -0 0</pose>
          <mass>0.6</mass>
          <inertia>
            <ixx>0.00123106</ixx>
            <ixy>0</ixy>
            <ixz>0</ixz>
            <iyy>0.00123106</iyy>
            <iyz>0</iyz>
            <izz>0.00123106</izz>
          </inertia>
        </inertial>
        <collision name='rear_right_wheel_link_collision'>
          <pose>0 0 0 1.5708 -0 0</pose>
          <geometry>
            <cylinder>
              <length>0.05</length>
              <radius>0.07162</radius>
            </cylinder>
          </geometry>
          <surface>
            <contact>
              <ode/>
            </contact>
            <friction>
              <ode>
                <mu>0.01</mu>
                <mu2>0.01</mu2>
              </ode>
              <torsional>
                <ode/>
              </torsional>
            </friction>
            <bounce/>
          </surface>
          <max_contacts>10</max_contacts>
        </collision>
        <visual name='rear_right_wheel_link_visual'>
          <pose>0 0 0 1.5708 -0 0</pose>
          <geometry>
            <cylinder>
              <length>0.05</length>
              <radius>0.07162</radius>
            </cylinder>
          </geometry>
          <material>
            <ambient>0.1764 0.4588 0.8509 1</ambient>
            <diffuse>0.1764 0.4588 0.8509 1</diffuse>
            <specular>0.1764 0.4588 0.8509 1</specular>
            <emissive>0 0 0 0</emissive>
          </material>
        </visual>
        <self_collide>0</self_collide>
        <enable_wind>0</enable_wind>
        <kinematic>0</kinematic>
      </link>
      <static>0</static>
      <plugin name='object_controller' filename='libgazebo_ros_planar_move.so'>
        <ros>
          <remapping>odom:=odom/unfiltered</remapping>
        </ros>
        <command_topic>cmd_vel</command_topic>
        <odometry_topic>odom/unfiltered</odometry_topic>
        <odometry_frame>odom</odometry_frame>
        <odometry_rate>20.0</odometry_rate>
        <robot_base_frame>base_footprint</robot_base_frame>
        <publish_odom>1</publish_odom>
        <publish_odom_tf>0</publish_odom_tf>
      </plugin>
      <pose>-2.011176 -1.699749 0 0 -0 -1.5708</pose>
    </model>
    <model name='abuRobocon_wall'>
      <pose>-0.006702 0.071414 0 0 -0 0</pose>
      <link name='Wall_38'>
        <collision name='Wall_38_Collision'>
          <geometry>
            <box>
              <size>8.14527 0.05 2.5</size>
            </box>
          </geometry>
          <pose>0 0 1.25 0 -0 0</pose>
          <max_contacts>10</max_contacts>
          <surface>
            <contact>
              <ode/>
            </contact>
            <bounce/>
            <friction>
              <torsional>
                <ode/>
              </torsional>
              <ode/>
            </friction>
          </surface>
        </collision>
        <visual name='Wall_38_Visual'>
          <pose>0 0 1.25 0 -0 0</pose>
          <geometry>
            <box>
              <size>8.14527 0.05 2.5</size>
            </box>
          </geometry>
          <material>
            <script>
              <uri>file://media/materials/scripts/gazebo.material</uri>
              <name>Gazebo/Grey</name>
            </script>
            <ambient>1 1 1 1</ambient>
          </material>
          <meta>
            <layer>0</layer>
          </meta>
        </visual>
        <pose>0.002832 -7.55513 0 0 -0 -0.000398</pose>
        <self_collide>0</self_collide>
        <enable_wind>0</enable_wind>
        <kinematic>0</kinematic>
      </link>
      <link name='Wall_45'>
        <collision name='Wall_45_Collision'>
          <geometry>
            <box>
              <size>8.1 0.05 2.5</size>
            </box>
          </geometry>
          <pose>0 0 1.25 0 -0 0</pose>
          <max_contacts>10</max_contacts>
          <surface>
            <contact>
              <ode/>
            </contact>
            <bounce/>
            <friction>
              <torsional>
                <ode/>
              </torsional>
              <ode/>
            </friction>
          </surface>
        </collision>
        <visual name='Wall_45_Visual'>
          <pose>0 0 1.25 0 -0 0</pose>
          <geometry>
            <box>
              <size>8.1 0.05 2.5</size>
            </box>
          </geometry>
          <material>
            <script>
              <uri>file://media/materials/scripts/gazebo.material</uri>
              <name>Gazebo/Grey</name>
            </script>
            <ambient>1 1 1 1</ambient>
          </material>
          <meta>
            <layer>0</layer>
          </meta>
        </visual>
        <pose>0.003543 7.55675 0 0 -0 3.14159</pose>
        <self_collide>0</self_collide>
        <enable_wind>0</enable_wind>
        <kinematic>0</kinematic>
      </link>
      <link name='Wall_47'>
        <collision name='Wall_47_Collision'>
          <geometry>
            <box>
              <size>15.1552 0.05 2.5</size>
            </box>
          </geometry>
          <pose>0 0 1.25 0 -0 0</pose>
          <max_contacts>10</max_contacts>
          <surface>
            <contact>
              <ode/>
            </contact>
            <bounce/>
            <friction>
              <torsional>
                <ode/>
              </torsional>
              <ode/>
            </friction>
          </surface>
        </collision>
        <visual name='Wall_47_Visual'>
          <pose>0 0 1.25 0 -0 0</pose>
          <geometry>
            <box>
              <size>15.1552 0.05 2.5</size>
            </box>
          </geometry>
          <material>
            <script>
              <uri>file://media/materials/scripts/gazebo.material</uri>
              <name>Gazebo/Grey</name>
            </script>
            <ambient>1 1 1 1</ambient>
          </material>
          <meta>
            <layer>0</layer>
          </meta>
        </visual>
        <pose>4.03951 -0.002303 0 0 -0 1.57225</pose>
        <self_collide>0</self_collide>
        <enable_wind>0</enable_wind>
        <kinematic>0</kinematic>
      </link>
      <link name='Wall_53'>
        <collision name='Wall_53_Collision'>
          <geometry>
            <box>
              <size>15.1538 0.05 2.5</size>
            </box>
          </geometry>
          <pose>0 0 1.25 0 -0 0</pose>
          <max_contacts>10</max_contacts>
          <surface>
            <contact>
              <ode/>
            </contact>
            <bounce/>
            <friction>
              <torsional>
                <ode/>
              </torsional>
              <ode/>
            </friction>
          </surface>
        </collision>
        <visual name='Wall_53_Visual'>
          <pose>0 0 1.25 0 -0 0</pose>
          <geometry>
            <box>
              <size>15.1538 0.05 2.5</size>
            </box>
          </geometry>
          <material>
            <script>
              <uri>file://media/materials/scripts/gazebo.material</uri>
              <name>Gazebo/Grey</name>
            </script>
            <ambient>1 1 1 1</ambient>
          </material>
          <meta>
            <layer>0</layer>
          </meta>
        </visual>
        <pose>-4.03596 -0.001617 0 0 -0 1.56888</pose>
        <self_collide>0</self_collide>
        <enable_wind>0</enable_wind>
        <kinematic>0</kinematic>
      </link>
      <static>1</static>
    </model>
  </world>
</sdf>
